<?xml version="1.0" ?>
<!-- =================================================================================== -->
<!-- |    This document was autogenerated by xacro from src/kinova_arm_description/description/kinova_arm.urdf.xacro | -->
<!-- |    EDITING THIS FILE BY HAND IS NOT RECOMMENDED                                 | -->
<!-- =================================================================================== -->
<robot name="kinova_arm">
  <!-- <xacro:include filename="$(find skratch_moveit_config)/config/skratch_base.ros2_control.xacro"/> -->
  <!-- <xacro:skratch_base_ros2_control name="kinova_arm" initial_positions_file="$(find skratch_moveit_config)/config/initial_positions.yaml"/> -->
  <link name="arm_base_link"/>
  <link name="kinova_base">
    <inertial>
      <origin rpy="0.0 0.0 0.0" xyz="0.0007117526096760857 0.07634930281943218 0.00010627340345302608"/>
      <mass value="1.697"/>
      <inertia ixx="0.004622" ixy="9E-06" ixz="6E-05" iyy="0.004495" iyz="9E-06" izz="0.002079"/>
    </inertial>
    <visual>
      <origin rpy="0.0 0.0 0.0" xyz="0.0 0.0 0.0"/>
      <geometry>
        <mesh filename="file:///home/chaitanya/learning/ros_workspace/install/kinova_arm_description/share/kinova_arm_description/meshes/arm/kinova_base.stl" scale="0.001 0.001 0.001"/>
      </geometry>
      <material name="carbon_fiber">
        <color rgba="0.792156862745098 0.819607843137255 0.933333333333333 1"/>
      </material>
    </visual>
    <collision>
      <origin rpy="0.0 0.0 0.0" xyz="0.0 0.0 0.0"/>
      <geometry>
        <mesh filename="file:///home/chaitanya/learning/ros_workspace/install/kinova_arm_description/share/kinova_arm_description/meshes/arm/kinova_base.stl" scale="0.001 0.001 0.001"/>
      </geometry>
    </collision>
  </link>
  <gazebo reference="kinova_base">
    <material>Gazebo/LightBlue</material>
  </gazebo>
  <joint name="arm_base_joint" type="fixed">
    <origin rpy="1.57 0.0 3.14" xyz="0.0 0.0 0.0"/>
    <parent link="arm_base_link"/>
    <child link="kinova_base"/>
  </joint>
  <link name="kinova_shoulder">
    <inertial>
      <origin rpy="0.0 0.0 0.0" xyz="0.07198810883830421 0.009804160395352531 1.1709966243007998e-08"/>
      <mass value="1.3773"/>
      <inertia ixx="0.00457" ixy="1E-06" ixz="2E-06" iyy="0.004831" iyz="0.000448" izz="0.001409"/>
    </inertial>
    <visual>
      <origin rpy="1.57 0 1.57" xyz="-0.009 0.0 -0.009"/>
      <geometry>
        <mesh filename="file:///home/chaitanya/learning/ros_workspace/install/kinova_arm_description/share/kinova_arm_description/meshes/arm/kinova_shoulder.stl" scale="0.001 0.001 0.001"/>
      </geometry>
      <material name="carbon_fiber">
        <color rgba="0.792156862745098 0.819607843137255 0.933333333333333 1"/>
      </material>
    </visual>
    <collision>
      <origin rpy="1.57 0 1.57" xyz="-0.009 0.0 -0.009"/>
      <geometry>
        <mesh filename="file:///home/chaitanya/learning/ros_workspace/install/kinova_arm_description/share/kinova_arm_description/meshes/arm/kinova_shoulder.stl" scale="0.001 0.001 0.001"/>
      </geometry>
    </collision>
  </link>
  <gazebo reference="kinova_shoulder">
    <material>Gazebo/LightBlue</material>
  </gazebo>
  <joint name="shoulder_joint" type="continuous">
    <origin rpy="0 0 0" xyz="0 0.154 0"/>
    <parent link="kinova_base"/>
    <child link="kinova_shoulder"/>
    <axis xyz="0.0 1.0 0.0"/>
  </joint>
  <link name="kinova_half_arm_one">
    <inertial>
      <origin rpy="0.0 0.0 0.0" xyz="0.09866225956007688 0.006787291572545321 2.2830542429196597e-06"/>
      <mass value="1.1636"/>
      <inertia ixx="0.011088" ixy="5E-06" ixz="0" iyy="0.001072" iyz="-0.000691" izz="0.011255"/>
    </inertial>
    <visual>
      <origin rpy="-1.57 0 1.57" xyz="0 0.0 -0.011"/>
      <geometry>
        <mesh filename="file:///home/chaitanya/learning/ros_workspace/install/kinova_arm_description/share/kinova_arm_description/meshes/arm/kinova_half_arm_one.stl" scale="0.001 0.001 0.001"/>
      </geometry>
      <material name="carbon_fiber">
        <color rgba="0.792156862745098 0.819607843137255 0.933333333333333 1"/>
      </material>
    </visual>
    <collision>
      <origin rpy="-1.57 0 1.57" xyz="0 0.0 -0.011"/>
      <geometry>
        <mesh filename="file:///home/chaitanya/learning/ros_workspace/install/kinova_arm_description/share/kinova_arm_description/meshes/arm/kinova_half_arm_one.stl" scale="0.001 0.001 0.001"/>
      </geometry>
    </collision>
  </link>
  <gazebo reference="kinova_half_arm_one">
    <material>Gazebo/LightBlue</material>
  </gazebo>
  <joint name="half_arm_one_joint" type="revolute">
    <origin rpy="0 0 0" xyz="0 0.126 0"/>
    <parent link="kinova_shoulder"/>
    <child link="kinova_half_arm_one"/>
    <axis xyz="0.0 0.0 1.0"/>
    <limit effort="1000" lower="-2.249729" upper="2.249729" velocity="1000"/>
  </joint>
  <link name="kinova_half_arm_two">
    <inertial>
      <origin rpy="0.0 0.0 0.0" xyz="0.09866225956007688 0.006787291572545321 2.2830542429196597e-06"/>
      <mass value="1.1636"/>
      <inertia ixx="0.010932" ixy="0" ixz="-7E-06" iyy="0.011127" iyz="0.000606" izz="0.001043"/>
    </inertial>
    <visual>
      <origin rpy="1.57 0 -1.57" xyz="0 0.22 0"/>
      <geometry>
        <mesh filename="file:///home/chaitanya/learning/ros_workspace/install/kinova_arm_description/share/kinova_arm_description/meshes/arm/kinova_half_arm_two.stl" scale="0.001 0.001 0.001"/>
      </geometry>
      <material name="carbon_fiber">
        <color rgba="0.792156862745098 0.819607843137255 0.933333333333333 1"/>
      </material>
    </visual>
    <collision>
      <origin rpy="1.57 0 -1.57" xyz="0 0.22 0"/>
      <geometry>
        <mesh filename="file:///home/chaitanya/learning/ros_workspace/install/kinova_arm_description/share/kinova_arm_description/meshes/arm/kinova_half_arm_two.stl" scale="0.001 0.001 0.001"/>
      </geometry>
    </collision>
  </link>
  <gazebo reference="kinova_half_arm_two">
    <material>Gazebo/LightBlue</material>
  </gazebo>
  <joint name="half_arm_two_joint" type="continuous">
    <origin rpy="0 0 0" xyz="0 0.2 -0.011"/>
    <parent link="kinova_half_arm_one"/>
    <child link="kinova_half_arm_two"/>
    <axis xyz="0.0 1.0 0.0"/>
  </joint>
  <link name="kinova_fore_arm">
    <inertial>
      <origin rpy="0.0 0.0 0.0" xyz="0.07607203845617713 0.00824223456213911 -1.8156195599589993e-08"/>
      <mass value="0.9302"/>
      <inertia ixx="0.008147" ixy="-1E-06" ixz="0" iyy="0.000631" iyz="-0.0005" izz="0.008316"/>
    </inertial>
    <visual>
      <origin rpy="-1.57 0 1.57" xyz="0 0 -0.012"/>
      <geometry>
        <mesh filename="file:///home/chaitanya/learning/ros_workspace/install/kinova_arm_description/share/kinova_arm_description/meshes/arm/kinova_fore_arm.stl" scale="0.001 0.001 0.001"/>
      </geometry>
      <material name="carbon_fiber">
        <color rgba="0.792156862745098 0.819607843137255 0.933333333333333 1"/>
      </material>
    </visual>
    <collision>
      <origin rpy="-1.57 0 1.57" xyz="0 0 -0.012"/>
      <geometry>
        <mesh filename="file:///home/chaitanya/learning/ros_workspace/install/kinova_arm_description/share/kinova_arm_description/meshes/arm/kinova_fore_arm.stl" scale="0.001 0.001 0.001"/>
      </geometry>
    </collision>
  </link>
  <gazebo reference="kinova_fore_arm">
    <material>Gazebo/LightBlue</material>
  </gazebo>
  <joint name="fore_arm_joint" type="revolute">
    <origin rpy="0 0 0" xyz="0 0.22 0"/>
    <parent link="kinova_half_arm_two"/>
    <child link="kinova_fore_arm"/>
    <axis xyz="0.0 0.0 1.0"/>
    <limit effort="1000" lower="-2.579597" upper="2.579597" velocity="1000"/>
  </joint>
  <link name="kinova_spherical_wrist_one">
    <inertial>
      <origin rpy="0.0 0.0 0.0" xyz="0.060574574716361816 0.009255380929244132 -3.3978512789246475e-09"/>
      <mass value="0.6781"/>
      <inertia ixx="0.001596" ixy="0" ixz="0" iyy="0.001607" iyz="0.000256" izz="0.000399"/>
    </inertial>
    <visual>
      <origin rpy="1.57 0 1.57" xyz="0 0 0"/>
      <geometry>
        <mesh filename="file:///home/chaitanya/learning/ros_workspace/install/kinova_arm_description/share/kinova_arm_description/meshes/arm/kinova_spherical_wrist_one.stl" scale="0.001 0.001 0.001"/>
      </geometry>
      <material name="carbon_fiber">
        <color rgba="0.792156862745098 0.819607843137255 0.933333333333333 1"/>
      </material>
    </visual>
    <collision>
      <origin rpy="1.57 0 1.57" xyz="0 0 0"/>
      <geometry>
        <mesh filename="file:///home/chaitanya/learning/ros_workspace/install/kinova_arm_description/share/kinova_arm_description/meshes/arm/kinova_spherical_wrist_one.stl" scale="0.001 0.001 0.001"/>
      </geometry>
    </collision>
  </link>
  <gazebo reference="kinova_spherical_wrist_one">
    <material>Gazebo/LightBlue</material>
  </gazebo>
  <joint name="spherical_wrist_one_joint" type="continuous">
    <origin rpy="0 0 0" xyz="0 0.21 -0.012"/>
    <parent link="kinova_fore_arm"/>
    <child link="kinova_spherical_wrist_one"/>
    <axis xyz="0.0 1.0 0.0"/>
  </joint>
  <link name="kinova_spherical_wrist_two">
    <inertial>
      <origin rpy="0.0 0.0 0.0" xyz="0.060574574716361816 0.009255380929244132 -3.3978512789246475e-09"/>
      <mass value="0.6781"/>
      <inertia ixx="0.001641" ixy="0" ixz="0" iyy="0.00041" iyz="-0.000278" izz="0.001641"/>
    </inertial>
    <visual>
      <origin rpy="1.57 3.14 1.57" xyz="0 0.1035 0"/>
      <geometry>
        <mesh filename="file:///home/chaitanya/learning/ros_workspace/install/kinova_arm_description/share/kinova_arm_description/meshes/arm/kinova_spherical_wrist_two.stl" scale="0.001 0.001 0.001"/>
      </geometry>
      <material name="carbon_fiber">
        <color rgba="0.792156862745098 0.819607843137255 0.933333333333333 1"/>
      </material>
    </visual>
    <collision>
      <origin rpy="1.57 3.14 1.57" xyz="0 0.1035 0"/>
      <geometry>
        <mesh filename="file:///home/chaitanya/learning/ros_workspace/install/kinova_arm_description/share/kinova_arm_description/meshes/arm/kinova_spherical_wrist_two.stl" scale="0.001 0.001 0.001"/>
      </geometry>
    </collision>
  </link>
  <gazebo reference="kinova_spherical_wrist_two">
    <material>Gazebo/LightBlue</material>
  </gazebo>
  <joint name="spherical_wrist_two_joint" type="revolute">
    <origin rpy="0 0 0" xyz="0 0.1035 0"/>
    <parent link="kinova_spherical_wrist_one"/>
    <child link="kinova_spherical_wrist_two"/>
    <axis xyz="0.0 0.0 1.0"/>
    <limit effort="1000" lower="-2.099631" upper="2.099631" velocity="1000"/>
  </joint>
  <link name="kinova_camera">
    <inertial>
      <origin rpy="0.0 0.0 0.0" xyz="0.060574574716361816 0.009255380929244132 -3.3978512789246475e-09"/>
      <mass value="0.5006"/>
      <inertia ixx="0.000587" ixy="3E-06" ixz="3E-06" iyy="0.000369" iyz="0.000118" izz="0.000609"/>
    </inertial>
    <visual>
      <origin rpy="-1.57 -1.57 0" xyz="0 0 0"/>
      <geometry>
        <mesh filename="file:///home/chaitanya/learning/ros_workspace/install/kinova_arm_description/share/kinova_arm_description/meshes/arm/kinova_camera.stl" scale="0.001 0.001 0.001"/>
      </geometry>
      <material name="carbon_fiber">
        <color rgba="0.792156862745098 0.819607843137255 0.933333333333333 1"/>
      </material>
    </visual>
    <collision>
      <origin rpy="-1.57 -1.57 0" xyz="0 0 0"/>
      <geometry>
        <mesh filename="file:///home/chaitanya/learning/ros_workspace/install/kinova_arm_description/share/kinova_arm_description/meshes/arm/kinova_camera.stl" scale="0.001 0.001 0.001"/>
      </geometry>
    </collision>
  </link>
  <gazebo reference="kinova_camera">
    <material>Gazebo/LightBlue</material>
  </gazebo>
  <joint name="camera_joint" type="continuous">
    <origin rpy="0 0 0" xyz="0 0.11 0"/>
    <parent link="kinova_spherical_wrist_two"/>
    <child link="kinova_camera"/>
    <axis xyz="0.0 1.0 0.0"/>
  </joint>
  <link name="gripper_base">
    <inertial>
      <origin rpy="0 0 0" xyz="0.00021987 -2.3546E-10 0.030163"/>
      <mass value="0.30915"/>
      <inertia ixx="0.00028972" ixy="-5.7879E-10" ixz="-1.8543E-06" iyy="0.00030737" iyz="1.682E-12" izz="0.00019914"/>
    </inertial>
    <visual>
      <origin rpy="-1.57 1.57 0" xyz="0 0 0"/>
      <geometry>
        <mesh filename="file:///home/chaitanya/learning/ros_workspace/install/kinova_arm_description/share/kinova_arm_description/meshes/gripper/gripper_base.stl" scale="0.001 0.001 0.001"/>
      </geometry>
      <material name="carbon_fiber">
        <color rgba="0.792156862745098 0.819607843137255 0.933333333333333 1"/>
      </material>
    </visual>
    <collision>
      <origin rpy="-1.57 1.57 0" xyz="0 0 0"/>
      <geometry>
        <mesh filename="file:///home/chaitanya/learning/ros_workspace/install/kinova_arm_description/share/kinova_arm_description/meshes/gripper/gripper_base.stl" scale="0.001 0.001 0.001"/>
      </geometry>
    </collision>
  </link>
  <gazebo reference="gripper_base">
    <material>Gazebo/LightBlue</material>
  </gazebo>
  <joint name="gripper_base_joint" type="fixed">
    <origin rpy="0 1.57 0" xyz="0 0.062 0"/>
    <parent link="kinova_camera"/>
    <child link="gripper_base"/>
  </joint>
  <link name="left_gripper_finger">
    <inertial>
      <origin rpy="0 0 0" xyz="0 0.004879 0.032487"/>
      <mass value="0.050913"/>
      <inertia ixx="2.592e-05" ixy="0" ixz="0" iyy="2.590e-05" iyz="0" izz="2.626e-06"/>
    </inertial>
    <visual>
      <origin rpy="0 0 0" xyz="0 0 0"/>
      <geometry>
        <mesh filename="file:///home/chaitanya/learning/ros_workspace/install/kinova_arm_description/share/kinova_arm_description/meshes/gripper/gripper_finger.stl" scale="0.001 0.001 0.001"/>
      </geometry>
      <material name="">
        <color rgba="0.1 0.1 0.1 1"/>
      </material>
    </visual>
    <collision>
      <origin rpy="0 0 0" xyz="0 0 0"/>
      <geometry>
        <mesh filename="file:///home/chaitanya/learning/ros_workspace/install/kinova_arm_description/share/kinova_arm_description/meshes/gripper/gripper_finger.stl" scale="0.001 0.001 0.001"/>
      </geometry>
    </collision>
  </link>
  <gazebo reference="left_gripper_finger">
    <material>Gazebo/Black</material>
  </gazebo>
  <joint name="left_finger_joint" type="prismatic">
    <origin rpy="0 1.57 1.57" xyz="-0.027 0.03 0"/>
    <parent link="gripper_base"/>
    <child link="left_gripper_finger"/>
    <axis xyz="0.0 1.0 0.0"/>
    <limit effort="1000" lower="-0.026" upper="0.0" velocity="1000"/>
  </joint>
  <link name="right_gripper_finger">
    <inertial>
      <origin rpy="0 0 0" xyz="0 0.004879 0.032487"/>
      <mass value="0.050913"/>
      <inertia ixx="2.592e-05" ixy="0" ixz="0" iyy="2.590e-05" iyz="0" izz="2.626e-06"/>
    </inertial>
    <visual>
      <origin rpy="0 0 0" xyz="0 0 0"/>
      <geometry>
        <mesh filename="file:///home/chaitanya/learning/ros_workspace/install/kinova_arm_description/share/kinova_arm_description/meshes/gripper/gripper_finger.stl" scale="0.001 0.001 0.001"/>
      </geometry>
      <material name="">
        <color rgba="0.1 0.1 0.1 1"/>
      </material>
    </visual>
    <collision>
      <origin rpy="0 0 0" xyz="0 0 0"/>
      <geometry>
        <mesh filename="file:///home/chaitanya/learning/ros_workspace/install/kinova_arm_description/share/kinova_arm_description/meshes/gripper/gripper_finger.stl" scale="0.001 0.001 0.001"/>
      </geometry>
    </collision>
  </link>
  <gazebo reference="right_gripper_finger">
    <material>Gazebo/Black</material>
  </gazebo>
  <joint name="right_finger_joint" type="prismatic">
    <origin rpy="-1.57 -1.57 0" xyz="0.027 0.03 0"/>
    <parent link="gripper_base"/>
    <child link="right_gripper_finger"/>
    <axis xyz="0.0 1.0 0.0"/>
    <limit effort="1000" lower="-0.026" upper="0.0" velocity="1000"/>
  </joint>
  <!-- <link name="kinova_camera_optical_frame"/>
    <joint name="kinova_camera_optical_joint" type="fixed">
        <origin xyz="0 0 0" rpy="0 1.57 1.57"/> 
        <parent link="kinova_camera"/>
        <child link="kinova_camera_optical_frame"/>
    </joint> -->
</robot>
